<?xml version="1.0"?>
<robot name="fishbot">


  <!-- Robot Footprint -->
  <!-- <link name="base_footprint"/>

  <joint name="base_joint" type="fixed">
    <parent link="base_footprint"/>
    <child link="base_link"/>
    <origin xyz="0.0 0.0 0.076" rpy="0 0 0"/>
  </joint> -->


  <!-- base link -->
  <link name="base_link">
  	<visual>
      <origin xyz="0 0 0.0" rpy="0 0 0"/>
      <geometry>
		<cylinder length="0.12" radius="0.10"/>
      </geometry>
      <material name="blue">
      	<color rgba="0.1 0.1 1.0 0.5" /> 
      </material>
    </visual>
    <collision>
      <origin xyz="0 0 0.0" rpy="0 0 0"/>
      <geometry>
		<cylinder length="0.12" radius="0.10"/>
      </geometry>
      <material name="blue">
      	<color rgba="0.1 0.1 1.0 0.5" /> 
      </material>
    </collision>
    <inertial>
      <mass value="0.2"/>
      <inertia ixx="0.0122666" ixy="0" ixz="0" iyy="0.0122666" iyz="0" izz="0.02"/>
    </inertial>
  </link>
    
  <!-- laser link -->
  <link name="laser_link">
    <visual>
      <origin xyz="0 0 0" rpy="0 0 0"/>
      <geometry>
        <cylinder length="0.02" radius="0.02"/>
      </geometry>
      <material name="black">
        <color rgba="0.0 0.0 0.0 0.5" /> 
      </material>
    </visual>
    <collision>
      <origin xyz="0 0 0" rpy="0 0 0"/>
      <geometry>
        <cylinder length="0.02" radius="0.02"/>
      </geometry>
      <material name="black">
        <color rgba="0.0 0.0 0.0 0.5" /> 
      </material>
    </collision>
    <inertial>
    <mass value="0.1"/>
      <inertia ixx="0.000190416666667" ixy="0" ixz="0" iyy="0.0001904" iyz="0" izz="0.00036"/>
    </inertial>
  </link>
  
  <!-- laser joint -->
  <joint name="laser_joint" type="fixed">
      <parent link="base_link" />
      <child link="laser_link" />
      <origin xyz="0 0 0.075" />
  </joint>

  <link name="imu_link">
  	<visual>
      <origin xyz="0 0 0.0" rpy="0 0 0"/>
      <geometry>
		    <box size="0.02 0.02 0.02"/>
      </geometry>
    </visual>
    <collision>
      <origin xyz="0 0 0.0" rpy="0 0 0"/>
      <geometry>
		    <box size="0.02 0.02 0.02"/>
      </geometry>
    </collision>
    <inertial>
      <mass value="0.1"/>
        <inertia ixx="0.000190416666667" ixy="0" ixz="0" iyy="0.0001904" iyz="0" izz="0.00036"/>
      </inertial>
  </link>

  <!-- imu joint -->
  <joint name="imu_joint" type="fixed">
      <parent link="base_link" />
      <child link="imu_link" />
      <origin xyz="0 0 0.02" />
  </joint>


  <link name="left_wheel_link">
      <visual>
        <origin xyz="0 0 0" rpy="1.57079 0 0"/>
        <geometry>
          <cylinder length="0.04" radius="0.032"/>
        </geometry>
          <material name="black">
            <color rgba="0.0 0.0 0.0 0.5" /> 
          </material>
      </visual>
      <collision>
        <origin xyz="0 0 0" rpy="1.57079 0 0"/>
        <geometry>
          <cylinder length="0.04" radius="0.032"/>
        </geometry>
          <material name="black">
            <color rgba="0.0 0.0 0.0 0.5" /> 
          </material>
      </collision>
      <inertial>
        <mass value="0.2"/>
          <inertia ixx="0.000190416666667" ixy="0" ixz="0" iyy="0.0001904" iyz="0" izz="0.00036"/>
        </inertial>
  </link>
    
  <link name="right_wheel_link">
      <visual>
        <origin xyz="0 0 0" rpy="1.57079 0 0"/>
        <geometry>
          <cylinder length="0.04" radius="0.032"/>
        </geometry>
          <material name="black">
            <color rgba="0.0 0.0 0.0 0.5" /> 
          </material>
      </visual>
      <collision>
        <origin xyz="0 0 0" rpy="1.57079 0 0"/>
        <geometry>
          <cylinder length="0.04" radius="0.032"/>
        </geometry>
          <material name="black">
            <color rgba="0.0 0.0 0.0 0.5" /> 
          </material>
      </collision>
      <inertial>
      <mass value="0.2"/>
      <inertia ixx="0.000190416666667" ixy="0" ixz="0" iyy="0.0001904" iyz="0" izz="0.00036"/>
    </inertial>
  </link>
    
  <joint name="left_wheel_joint" type="continuous">
      <parent link="base_link" />
      <child link="left_wheel_link" />
      <origin xyz="-0.02 0.10 -0.06" />
      <axis xyz="0 1 0" />
  </joint>

  <joint name="right_wheel_joint" type="continuous">
      <parent link="base_link" />
      <child link="right_wheel_link" />
      <origin xyz="-0.02 -0.10 -0.06" />
      <axis xyz="0 1 0" />
  </joint>

  <link name="caster_link">
      <visual>
        <origin xyz="0 0 0" rpy="1.57079 0 0"/>
        <geometry>
            <sphere radius="0.016"/>
        </geometry>
          <material name="black">
            <color rgba="0.0 0.0 0.0 0.5" /> 
          </material>
      </visual>
      <collision>
        <origin xyz="0 0 0" rpy="1.57079 0 0"/>
        <geometry>
            <sphere radius="0.016"/>
        </geometry>
          <material name="black">
            <color rgba="0.0 0.0 0.0 0.5" /> 
          </material>
      </collision>
      <inertial>
      <mass value="0.02"/>
      <inertia ixx="0.000190416666667" ixy="0" ixz="0" iyy="0.0001904" iyz="0" izz="0.00036"/>
    </inertial>
  </link>
    
  <joint name="caster_joint" type="fixed">
      <parent link="base_link" />
      <child link="caster_link" />
      <origin xyz="0.06 0.0 -0.076" />
      <axis xyz="0 1 0" />
  </joint>

  <!-- arm -->
    <!-- <link name="world" />
    <joint name="world_joint" type="fixed">
        <origin xyz="0 0 0" rpy="0 0 0" />
        <parent link="world" />
        <child link="base_link2" />
    </joint> -->

    <link name="base_link2">
        <inertial>
            <origin xyz="0.00039768 8.0247E-10 0.012605" rpy="0 0 0" />
            <mass value="0.41542" />
            <inertia ixx="0.00054632" ixy="-4.5067E-09" ixz="5.9528E-07" iyy="0.00053741" iyz="-3.5275E-10" izz="0.0010336" />
        </inertial>
        <visual>
            <origin xyz="0 0 0" rpy="0 0 0" />
            <geometry>
                <mesh filename="package://elite_description/meshes/ec66/base_link.STL" />
            </geometry>
            <material name="">
                <color rgba="0.89412 0.91373 0.92941 1" />
            </material>
        </visual>
        <collision>
            <origin xyz="0 0 0" rpy="0 0 0" />
            <geometry>
                <mesh filename="package://elite_description/meshes/ec66/base_link.STL" />
            </geometry>
        </collision>
    </link>
    <link name="link1">
        <inertial>
            <origin xyz="3.9336E-06 -0.0082614 0.0028405" rpy="0 0 0" />
            <mass value="1.7827" />
            <inertia ixx="0.0031691" ixy="-1.2175E-07" ixz="-2.8349E-08" iyy="0.0029334" iyz="0.00037927" izz="0.0035086" />
        </inertial>
        <visual>
            <origin xyz="0 0 0" rpy="0 0 0" />
            <geometry>
                <mesh filename="package://elite_description/meshes/ec66/link1.STL" />
            </geometry>
            <material name="">
                <color rgba="1 1 1 1" />
            </material>
        </visual>
        <collision>
            <origin xyz="0 0 0" rpy="0 0 0" />
            <geometry>
                <mesh filename="package://elite_description/meshes/ec66/link1.STL" />
            </geometry>
        </collision>
    </link>
    <joint name="joint1" type="revolute">
        <origin xyz="0 0 0.096" rpy="0 0 3.1416" />
        <parent link="base_link2" />
        <child link="link1" />
        <axis xyz="0 0 1" />
        <limit lower="-6.2832" upper="6.2832" effort="150.0" velocity="2.61993" />
        <dynamics damping="0" friction="0" />
    </joint>
    <link name="link2">
        <inertial>
            <origin xyz="-2.17E-06 0.17637 0.13932" rpy="0 0 0" />
            <mass value="4.8843" />
            <inertia ixx="0.022101" ixy="-1.0832E-07" ixz="-1.2727E-07" iyy="0.0066105" iyz="-0.00021178" izz="0.022526" />
        </inertial>
        <visual>
            <origin xyz="0 0 0" rpy="0 0 0" />
            <geometry>
                <mesh filename="package://elite_description/meshes/ec66/link2.STL" />
            </geometry>
            <material name="">
                <color rgba="1 1 1 1" />
            </material>
        </visual>
        <collision>
            <origin xyz="0 0 0" rpy="0 0 0" />
            <geometry>
                <mesh filename="package://elite_description/meshes/ec66/link2.STL" />
            </geometry>
        </collision>
    </link>
    <joint name="joint2" type="revolute">
        <origin xyz="0 0 0" rpy="1.5708 -1.5708 0" />
        <parent link="link1" />
        <child link="link2" />
        <axis xyz="0 0 1" />
        <limit lower="-6.2832" upper="6.2832" effort="150.0" velocity="2.61993" />
        <dynamics damping="0" friction="0" />
    </joint>
    <link name="link3">
        <inertial>
            <origin xyz="0.20069 -7.9845E-06 0.028008" rpy="0 0 0" />
            <mass value="2.1495" />
            <inertia ixx="0.0015747" ixy="-2.8912E-08" ixz="7.3471E-05" iyy="0.0091566" iyz="-1.4815E-07" izz="0.0091573" />
        </inertial>
        <visual>
            <origin xyz="0 0 0" rpy="0 0 0" />
            <geometry>
                <mesh filename="package://elite_description/meshes/ec66/link3.STL" />
            </geometry>
            <material name="">
                <color rgba="1 1 1 1" />
            </material>
        </visual>
        <collision>
            <origin xyz="0 0 0" rpy="0 0 0" />
            <geometry>
                <mesh filename="package://elite_description/meshes/ec66/link3.STL" />
            </geometry>
        </collision>
    </link>
    <joint name="joint3" type="revolute">
        <origin xyz="0 0.418 0" rpy="0 0 1.5708" />
        <parent link="link2" />
        <child link="link3" />
        <axis xyz="0 0 1" />
        <limit lower="-2.7925" upper="2.7925" effort="150.0" velocity="3.31613" />
        <dynamics damping="0" friction="0" />
    </joint>
    <link name="link4">
        <inertial>
            <origin xyz="-5.2274E-07 -0.00070291 -0.006006" rpy="0 0 0" />
            <mass value="0.53436" />
            <inertia ixx="0.00041486" ixy="-4.7177E-09" ixz="-1.1841E-09" iyy="0.0004403" iyz="-5.8283E-05" izz="0.00037669" />
        </inertial>
        <visual>
            <origin xyz="0 0 0" rpy="0 0 0" />
            <geometry>
                <mesh filename="package://elite_description/meshes/ec66/link4.STL" />
            </geometry>
            <material name="">
                <color rgba="1 1 1 1" />
            </material>
        </visual>
        <collision>
            <origin xyz="0 0 0" rpy="0 0 0" />
            <geometry>
                <mesh filename="package://elite_description/meshes/ec66/link4.STL" />
            </geometry>
        </collision>
    </link>
    <joint name="joint4" type="revolute">
        <origin xyz="0.398 0 0.122" rpy="0 0 0" />
        <parent link="link3" />
        <child link="link4" />
        <axis xyz="0 0 1" />
        <limit lower="-6.2832" upper="6.2832" effort="28.0" velocity="4.53786" />
        <dynamics damping="0" friction="0" />
    </joint>
    <link name="link5">
        <inertial>
            <origin xyz="5.2283E-07 0.00070291 -0.006006" rpy="0 0 0" />
            <mass value="0.53436" />
            <inertia ixx="0.00041486" ixy="-4.6787E-09" ixz="1.1524E-09" iyy="0.0004403" iyz="5.8283E-05" izz="0.00037669" />
        </inertial>
        <visual>
            <origin xyz="0 0 0" rpy="0 0 0" />
            <geometry>
                <mesh filename="package://elite_description/meshes/ec66/link5.STL" />
            </geometry>
            <material name="">
                <color rgba="1 1 1 1" />
            </material>
        </visual>
        <collision>
            <origin xyz="0 0 0" rpy="0 0 0" />
            <geometry>
                <mesh filename="package://elite_description/meshes/ec66/link5.STL" />
            </geometry>
        </collision>
    </link>
    <joint name="joint5" type="revolute">
        <origin xyz="0 0.098 0" rpy="1.5708 0 -3.1416" />
        <parent link="link4" />
        <child link="link5" />
        <axis xyz="0 0 1" />
        <limit lower="-6.2832" upper="6.2832" effort="28.0" velocity="4.53786" />
        <dynamics damping="0" friction="0" />
    </joint>
    <link name="link6">
        <inertial>
            <origin xyz="-1.7556E-08 -0.00045052 -0.021169" rpy="0 0 0" />
            <mass value="0.16488" />
            <inertia ixx="7.7869E-05" ixy="-3.3531E-10" ixz="1.915E-10" iyy="7.757E-05" iyz="-7.8331E-08" izz="0.00011744" />
        </inertial>
        <visual>
            <origin xyz="0 0 0" rpy="0 0 0" />
            <geometry>
                <mesh filename="package://elite_description/meshes/ec66/link6.STL" />
            </geometry>
            <material name="">
                <color rgba="0.79216 0.81961 0.93333 1" />
            </material>
        </visual>
        <collision>
            <origin xyz="0 0 0" rpy="0 0 0" />
            <geometry>
                <mesh filename="package://elite_description/meshes/ec66/link6.STL" />
            </geometry>
        </collision>
    </link>
    <joint name="joint6" type="revolute">
        <origin xyz="0 -0.089 0" rpy="-1.5708 0 3.1416" />
        <parent link="link5" />
        <child link="link6" />
        <axis xyz="0 0 1" />
        <limit lower="-6.2832" upper="6.2832" effort="28.0" velocity="4.53786" />
        <dynamics damping="0" friction="0" />
    </joint>
    <link name="flan" />
    <joint name="flan_joint" type="fixed">
        <origin xyz="0 0 0" rpy="0 0 0" />
        <parent link="link6" />
        <child link="flan" />
    </joint>




  <gazebo reference="caster_link">
    <material>Gazebo/Black</material>
  </gazebo>

  <gazebo reference="caster_link">
    <mu1 value="0.0"/>
    <mu2 value="0.0"/>
    <kp value="1000000.0" />
    <kd value="10.0" />
    <!-- <fdir1 value="0 0 1"/> -->
  </gazebo>


  <gazebo>
    <plugin name='diff_drive' filename='libgazebo_ros_diff_drive.so'>
          <ros>
            <namespace>/</namespace>
            <remapping>cmd_vel:=cmd_vel</remapping>
            <remapping>odom:=odom</remapping>
          </ros>
          <update_rate>30</update_rate>
          <!-- wheels -->
          <!-- <left_joint>left_wheel_joint</left_joint> -->
          <!-- <right_joint>right_wheel_joint</right_joint> -->
          <left_joint>left_wheel_joint</left_joint>
          <right_joint>right_wheel_joint</right_joint>
          <!-- kinematics -->
          <wheel_separation>0.2</wheel_separation>
          <wheel_diameter>0.065</wheel_diameter>
          <!-- limits -->
          <max_wheel_torque>20</max_wheel_torque>
          <max_wheel_acceleration>1.0</max_wheel_acceleration>
          <!-- output -->
          <publish_odom>true</publish_odom>
          <publish_odom_tf>true</publish_odom_tf>
          <publish_wheel_tf>false</publish_wheel_tf>
          <odometry_frame>odom</odometry_frame>
          <robot_base_frame>base_footprint</robot_base_frame>
      </plugin>


      <plugin name="fishbot_joint_state" filename="libgazebo_ros_joint_state_publisher.so">
        <ros>
          <remapping>~/out:=joint_states</remapping>
        </ros>
        <update_rate>30</update_rate>
        <joint_name>right_wheel_joint</joint_name>
        <joint_name>left_wheel_joint</joint_name>
      </plugin>    
      </gazebo> 

      <gazebo reference="laser_link">
        <material>Gazebo/Black</material>
      </gazebo>

    <gazebo reference="imu_link">
      <sensor name="imu_sensor" type="imu">
      <plugin filename="libgazebo_ros_imu_sensor.so" name="imu_plugin">
          <ros>
            <namespace>/</namespace>
            <remapping>~/out:=imu</remapping>
          </ros>
          <initial_orientation_as_reference>false</initial_orientation_as_reference>
        </plugin>
        <always_on>true</always_on>
        <update_rate>100</update_rate>
        <visualize>true</visualize>
        <imu>
          <angular_velocity>
            <x>
              <noise type="gaussian">
                <mean>0.0</mean>
                <stddev>2e-4</stddev>
                <bias_mean>0.0000075</bias_mean>
                <bias_stddev>0.0000008</bias_stddev>
              </noise>
            </x>
            <y>
              <noise type="gaussian">
                <mean>0.0</mean>
                <stddev>2e-4</stddev>
                <bias_mean>0.0000075</bias_mean>
                <bias_stddev>0.0000008</bias_stddev>
              </noise>
            </y>
            <z>
              <noise type="gaussian">
                <mean>0.0</mean>
                <stddev>2e-4</stddev>
                <bias_mean>0.0000075</bias_mean>
                <bias_stddev>0.0000008</bias_stddev>
              </noise>
            </z>
          </angular_velocity>
          <linear_acceleration>
            <x>
              <noise type="gaussian">
                <mean>0.0</mean>
                <stddev>1.7e-2</stddev>
                <bias_mean>0.1</bias_mean>
                <bias_stddev>0.001</bias_stddev>
              </noise>
            </x>
            <y>
              <noise type="gaussian">
                <mean>0.0</mean>
                <stddev>1.7e-2</stddev>
                <bias_mean>0.1</bias_mean>
                <bias_stddev>0.001</bias_stddev>
              </noise>
            </y>
            <z>
              <noise type="gaussian">
                <mean>0.0</mean>
                <stddev>1.7e-2</stddev>
                <bias_mean>0.1</bias_mean>
                <bias_stddev>0.001</bias_stddev>
              </noise>
            </z>
          </linear_acceleration>
        </imu>
      </sensor>
    </gazebo>

    <gazebo reference="laser_link">
      <sensor name="laser_sensor" type="ray">
      <always_on>true</always_on>
      <visualize>true</visualize>
      <update_rate>5</update_rate>
      <pose>0 0 0.075 0 0 0</pose>
      <ray>
          <scan>
            <horizontal>
              <samples>360</samples>
              <resolution>1.000000</resolution>
              <min_angle>0.000000</min_angle>
              <max_angle>6.280000</max_angle>
            </horizontal>
          </scan>
          <range>
            <min>0.120000</min>
            <max>3.5</max>
            <resolution>0.015000</resolution>
          </range>
          <noise>
            <type>gaussian</type>
            <mean>0.0</mean>
            <stddev>0.01</stddev>
          </noise>
      </ray>

      <plugin name="laserscan" filename="libgazebo_ros_ray_sensor.so">
        <ros>
          <!-- <namespace>/tb3</namespace> -->
          <remapping>~/out:=scan</remapping>
        </ros>
        <output_type>sensor_msgs/LaserScan</output_type>
        <frame_name>laser_link</frame_name>
      </plugin>
      </sensor>
    </gazebo>
    
    <gazebo reference="caster_link">
        <material>Gazebo/Black</material>
    </gazebo>


</robot>